Workbook

Sheet GOV'T AGENCIES
E8: YOUR GROWTH OPPORTUNITY IS WITH DBP! | L8: CUSTOMIZED EVALUATION (GH & BH APPROVAL)
E9: INPUT DATA ON WHITE CELLS | I9: =NOW() -> 46084.283 | L9: 2018 GAA NTHP | M9: 5000 | P9: =DAY(EOMONTH(I9,0)) -> 31 | Q9: Month-end date | R9: LOAN EVALUATION GUIDE
G10: LOANS FOR TAKE-OUT | H10: BALANCE | I10: AMORT | L10: BPI days | M10: =$P$9-DAY(I9) -> 28 | N10: Prevailing Parameter
E11: TYPE: [1] FOR RENEWAL/RE-AVAILMENT OR [0] FOR NEW | F11: 0 | G11: LOAN 1 | H11: 0 | I11: 0 | L11: MAX AMORT: | M11: =F50 -> 2000 | N11: =IF(F49<F47,"BASED ON IGIR","BASED ON NTHP") -> BASED ON NTHP | R11: Min Loan Amount to Pay-off Everything | S11: =(F14+H15)/0.97947 -> 0 | U11: NET PROCEEDS | V11: =S11-H15-F14-W47 -> -6304
E12: GROSS SALARY | G12: LOAN 2 | N12: Net Proceeds
E13: NET SALARY (OR NET TAKE HOME PAY) | G13: LOAN 3 | H13: 0 | I13: 0 | L13: LOAN AMOUNT | M13: 150000 | N13: =M13-F14-H15-W47 -> 143696 | R13: ORIGINAL EFFECTIVE NTHP | S13: ='NEW BORROWER'!C5 -> 8000
E14: OUTSTANDING BALANCE OF EXISTING DBP LOAN | F14: 0 | G14: LOAN 4 | H14: 0 | I14: 0 | L14: TERM | M14: AMORT/MO | N14: Remarks | R14: TERM | S14: AMORT/MO | T14: IGIR RATIO | U14: NTHP | V14: INC / DEC IN NTHP
E15: MONTHLY AMORTIZATION OF EXISTING DBP LOAN | F15: 0 | G15: TOTAL | H15: =SUM(H11:H14) -> 0 | I15: =SUM(I11:I14) -> 0 | L15: 4 YRS | M15: =IF('NEW BORROWER'!B11=0,0,-PMT('NEW BORROWER'!B10/12,48,M13)) -> 0 | N15: =IF('NEW BORROWER'!B11=0,"N.A.",IF(M15>$M$11,"CANNOT BE","OK")) -> N.A. | R15: 4 YRS | S15: =-PMT('NEW BORROWER'!B10/12,48,M13) -> 4174.6122 | T15: =S15/'NEW BORROWER'!$C$3 -> 0.27830748 | U15: ='NEW BORROWER'!$C$5+$I$15+$F$15-S15 -> 3825.3878 | V15: =U15-S13 -> -4174.6122
L16: 3 YRS | M16: =-PMT('NEW BORROWER'!C10/12,36,M13) -> 4982.1465 | N16: =IF(M16>$M$11,"CANNOT BE","OK") -> CANNOT BE | R16: 3 YRS | S16: =-PMT('NEW BORROWER'!C10/12,36,M13) -> 4982.1465 | T16: =S16/'NEW BORROWER'!$C$3 -> 0.3321431 | U16: ='NEW BORROWER'!$C$5+$I$15+$F$15-S16 -> 3017.8535 | V16: =U16-('NEW BORROWER'!$C$5-$I$15) -> -4982.1465
F17: NEW | L17: 2 YRS | M17: =-PMT('NEW BORROWER'!D10/12,24,M13) -> 7061.0208 | N17: =IF(M17>$M$11,"CANNOT BE","OK") -> CANNOT BE
L18: 1 YR | M18: =-PMT('NEW BORROWER'!E10/12,12,M13) -> 13327.318 | N18: =IF(M18>$M$11,"CANNOT BE","OK") -> CANNOT BE | R18: 2 YRS | S18: =-PMT('NEW BORROWER'!D10/12,24,M13) -> 7061.0208 | T18: =S18/'NEW BORROWER'!$C$3 -> 0.47073472 | U18: ='NEW BORROWER'!$C$5+$I$15+$F$15-S18 -> 938.97917 | V18: =U18-('NEW BORROWER'!$C$5-$I$15) -> -7061.0208
R19: 1 YR | S19: =-PMT('NEW BORROWER'!E10/12,12,M13) -> 13327.318 | T19: =S19/'NEW BORROWER'!$C$3 -> 0.88848789 | U19: ='NEW BORROWER'!$C$5+$I$15+$F$15-S19 -> -5327.3183 | V19: =U19-('NEW BORROWER'!$C$5-$I$15) -> -13327.318
L21: AMORT/MO | M21: 6500 | N21: =IF(M21>M11,"CANNOT BE","OK") -> CANNOT BE
L22: TERM | M22: AMOUNT | N22: Net Proceeds
L23: 4 YRS | M23: =IF('NEW BORROWER'!B11=0,0,-PV('NEW BORROWER'!B10/12,48,M21)) -> 0 | N23: =M23-$F$14-$H$15-W37 -> 0
L24: 3 YRS | M24: =-PV('NEW BORROWER'!C10/12,36,M21) -> 195698.78 | N24: =M24-$F$14-$H$15-W38 -> 189344.8
F25: RENEWAL/REAVAILMENT | L25: 2 YRS | M25: =-PV('NEW BORROWER'!D10/12,24,M21) -> 138082.02 | N25: =M25-$F$14-$H$15-W39 -> 133859.01
E26: TERM | F26: 4 YRS | G26: 3 YRS | H26: 2 YRS | I26: 1 YR | L26: 1 YR | M26: =-PV('NEW BORROWER'!E10/12,12,M21) -> 73158.004 | N26: =M26-$F$14-$H$15-W40 -> 71097.63
E27: INTEREST RATE (PER ANNUM) | F27: 0.1 | G27: 0.08 | H27: 0.08 | I27: 0.08
E28: MAXIMUM LOANABLE AMOUNT | F28: =IF(F61<48,0,ROUNDDOWN(-PV(F27/12,48,F60),-3)) -> 0 | G28: =ROUNDDOWN(-PV(G27/12,36,F60),-3) -> 95000 | H28: =ROUNDDOWN(-PV(H27/12,24,F60),-3) -> 66000 | I28: =ROUNDDOWN(-PV(I27/12,12,F60),-3) -> 34000
E29: MONTHLY AMORTIZATION | F29: =-PMT(F27/12,48,F28) -> 0 | G29: =-PMT(G27/12,36,G28) -> 2976.9547 | H29: =-PMT(H27/12,24,H28) -> 2985.0012 | I29: =-PMT(I27/12,12,I28) -> 2957.6066
E30: ESTIMATED NET PROCEEDS | F30: =F28-F14-F41-H15 -> 0 | G30: =G28-F14-G41-H15 -> 92911.8 | H30: =H28-F14-H41-H15 -> 64715.5 | I30: =I28-F14-I41-H15 -> 33380.407
E31: NET TAKE HOME PAY | F31: ='NEW BORROWER'!$C$5-F29+$F$15+$I$15 -> 8000 | G31: ='NEW BORROWER'!$C$5-G29+$F$15+$I$15 -> 5023.0453 | H31: ='NEW BORROWER'!$C$5-H29+$F$15+$I$15 -> 5014.9988 | I31: ='NEW BORROWER'!$C$5-I29+$F$15+$I$15 -> 5042.3934
E33: THANK YOU FOR BANKING WITH DBP!
I34: COPY RIGHTS: DBP Cebu & Catbalogan Branches
E35: COMPUTATIONS | S35: SCHEDULE OF FEES - BASED ON DESIRED LOAN AMORT
N36: =N13/M13 -> 0.95797333 | S36: SF | T36: DST | U36: MRI | V36: BPI | W36: TOTAL
E37: SERVICE FEE | F37: =IF('NEW BORROWER'!B11*1%<1500,'NEW BORROWER'!B11*1%,1500) -> 0 | G37: =IF('NEW BORROWER'!C11*1%<1500,'NEW BORROWER'!C11*1%,1500) -> 600 | H37: =IF('NEW BORROWER'!D11*1%<1500,'NEW BORROWER'!D11*1%,1500) -> 420 | I37: =IF('NEW BORROWER'!E11*1%<1500,'NEW BORROWER'!E11*1%,1500) -> 220 | R37: 4 | S37: =IF(M23*1%<1500,M23*1%,1500) -> 0 | T37: =IF(M23<250000,0,M23/200) -> 0 | U37: =(M23/1000)*G100 -> 0 | V37: =M23*$M$10*'NEW BORROWER'!B10/360 -> 0 | W37: =SUM(S37:V37) -> 0
E38: DOC STAMPS | F38: =IF('NEW BORROWER'!B11<250000,0,'NEW BORROWER'!B11*1.5/200) -> 0 | G38: =IF('NEW BORROWER'!C11<250000,0,'NEW BORROWER'!C11*1.5/200) -> 0 | H38: =IF('NEW BORROWER'!D11<250000,0,'NEW BORROWER'!D11*1.5/200) -> 0 | I38: =IF('NEW BORROWER'!E11<250000,0,'NEW BORROWER'!E11*1.5/200) -> 0 | R38: 3 | S38: =IF(M24*1%<1500,M24*1%,1500) -> 1500 | T38: =IF(M24<250000,0,M24/200) -> 0 | U38: =(M24/1000)*G99 -> 3027.4602 | V38: =M24*$M$10*'NEW BORROWER'!C10/360 -> 1826.522 | W38: =SUM(S38:V38) -> 6353.9821
E39: Max Broken Period Interest | F39: ='NEW BORROWER'!B11*'NEW BORROWER'!B10*$M$10/360 -> 0 | G39: ='NEW BORROWER'!C11*'NEW BORROWER'!C10*$M$10/360 -> 560 | H39: ='NEW BORROWER'!D11*'NEW BORROWER'!D10*$M$10/360 -> 392 | I39: ='NEW BORROWER'!E11*'NEW BORROWER'!E10*$M$10/360 -> 205.33333 | R39: 2 | S39: =IF(M25*1%<1500,M25*1%,1500) -> 1380.8202 | T39: =IF(M25<250000,0,M25/200) -> 0 | U39: =(M25/1000)*G98 -> 1553.4227 | V39: =M25*$M$10*'NEW BORROWER'!D10/360 -> 1288.7655 | W39: =SUM(S39:V39) -> 4223.0084
E40: MRI | F40: =('NEW BORROWER'!B11/1000)*G100 -> 0 | G40: ='NEW BORROWER'!C11*G99/1000 -> 928.2 | H40: ='NEW BORROWER'!D11*G98/1000 -> 472.5 | I40: ='NEW BORROWER'!E11*G97/1000 -> 194.26 | R40: 1 | S40: =IF(M26*1%<1500,M26*1%,1500) -> 731.58004 | T40: =IF(M26<250000,0,M26/200) -> 0 | U40: =(M26/1000)*G97 -> 645.98517 | V40: =M26*$M$10*'NEW BORROWER'!E10/360 -> 682.80803 | W40: =SUM(S40:V40) -> 2060.3732
E41: TOTAL FEES/CHARGES | F41: =SUM(F37:F40) -> 0 | G41: =SUM(G37:G40) -> 2088.2 | H41: =SUM(H37:H40) -> 1284.5 | I41: =SUM(I37:I40) -> 619.59333
S42: SCHEDULE OF FEES BASED ON DESIRED LOAN AMOUNT
E43: COMPUTATIONS FOR LOANABLE AMOUNT PARAMETERS - GROUP HEAD AND BH AUTHORITY
E45: NTHP ADD DBP LOAN AND OTHER LOANS | F45: ='NEW BORROWER'!C5+F15+I15 -> 8000 | S45: SF | T45: DST | U45: MRI | V45: BPI | W45: TOTAL
E46: NTHP COMPUTATION TO PER NTHP TABLE | F46: =IF(F11>0,M9,IF('NEW BORROWER'!C3<18000,H68,IF('NEW BORROWER'!C3<38000,H69,H70))) -> 6000
E47: NTHP LESS GAA REQ | F47: =F45-F46 -> 2000 | S47: =IF(M13*1%<1500,M37*1%,1500) -> 1500 | T47: =IF(M13<250000,0,M13/200) -> 0 | U47: =(M13/1000)*G100 -> 3054 | V47: =M13*$M$10*'NEW BORROWER'!B10/360 -> 1750 | W47: =SUM(S47:V47) -> 6304
E48: IGIR TO USE | F48: =IF(F11>0,IF('NEW BORROWER'!C3<10000,20%,IF('NEW BORROWER'!C3<13000,30%,IF('NEW BORROWER'!C3<38000,35%,40%))),IF('NEW BORROWER'!C3<10000,10%,IF('NEW BORROWER'!C3<13000,25%,30%))) -> 0.3
E49: LOAN INSTALLMENT (LI) | F49: =F48*'NEW BORROWER'!C3 -> 4500
E50: INSTALLMENT TO USE | F50: =IF(F47<F49,F47,F49) -> 2000
...

Sheet NEW BORROWER
A1: LOAN CALCULATOR FOR NEW BORROWER
A3: Gross Salary for Latest Month (Basic and PERA only): P | C3: 15000
A5: Net Pay for the Latest Month: P | C5: 8000
A9: TERM IN YEARS: | B9: 4 YRS | C9: 3 YRS | D9: 2 YRS | E9: 1 YR
A10: INTEREST RATE PER ANNUM: | B10: 0.15 | C10: 0.12 | D10: 0.12 | E10: 0.12
A11: MAXIMUM LOAN AMOUNT: | B11: =IF('GOV''T AGENCIES'!F51<48,0,ROUNDDOWN(-PV(B10/12,48,'GOV''T AGENCIES'!F50),-3)) -> 0 | C11: =ROUNDDOWN(-PV(C10/12,36,'GOV''T AGENCIES'!F50),-3) -> 60000 | D11: =ROUNDDOWN(-PV(D10/12,24,'GOV''T AGENCIES'!F50),-3) -> 42000 | E11: =ROUNDDOWN(-PV(E10/12,12,'GOV''T AGENCIES'!F50),-3) -> 22000
A12: MONTHLY AMORTIZATION: | B12: =-PMT(B10/12,48,B11) -> 0 | C12: =-PMT(C10/12,36,C11) -> 1992.8586 | D12: =-PMT(D10/12,24,D11) -> 1977.0858 | E12: =-PMT(E10/12,12,E11) -> 1954.6734
A13: ESTIMATED NET PROCEEDS: | B13: =B11-'GOV''T AGENCIES'!F14-'GOV''T AGENCIES'!F41-'GOV''T AGENCIES'!H15 -> 0 | C13: =C11-'GOV''T AGENCIES'!F14-'GOV''T AGENCIES'!G41-'GOV''T AGENCIES'!H15 -> 57911.8 | D13: =D11-'GOV''T AGENCIES'!F14-'GOV''T AGENCIES'!H41-'GOV''T AGENCIES'!H15 -> 40715.5 | E13: =E11-'GOV''T AGENCIES'!F14-'GOV''T AGENCIES'!I41-'GOV''T AGENCIES'!H15 -> 21380.407

Sheet DAR
E8: YOUR FINANCING OPPORTUNITY WITH DBP
E9: INPUT DATA ON WHITE CELLS | N9: Prevailing Factor
G10: LOANS FOR TAKE-OUT | H10: BALANCE | I10: AMORT | L10: MAX AMORT: | M10: =F37 -> 20000 | N10: =IF(F36<F34,"BASED ON IGIR","BASED ON NTHP") -> BASED ON IGIR
E11: TYPE: [1] FOR RENEWAL/RE-AVAILMENT OR [0] FOR NEW | F11: 1 | G11: LOAN 1 | H11: 40000 | I11: 3000 | N11: Net Proceeds
E12: GROSS SALARY | F12: 50000 | G12: LOAN 2 | H12: 50000 | I12: 2000 | L12: LOAN AMOUNT | M12: 759400 | N12: =(0.97912334*M12-F14)-H15 -> 593546.26
E13: NET SALARY (OR NET TAKE HOME PAY) | F13: 30000 | G13: LOAN 3 | H13: 30000 | I13: 3000 | L13: TERM | M13: AMORT/MO | N13: Remarks
E14: OUTSTANDING BALANCE OF EXISTING DBP LOAN | F14: 0 | G14: LOAN 4 | H14: 30000 | I14: 2000 | L14: 4 YRS | M14: =-PMT(F18/12,48,M12) -> 19997.915 | N14: =IF(M14>$M$10,"CANNOT BE","OK") -> OK
E15: MONTHLY AMORTIZATION OF EXISTING DBP LOAN | F15: 0 | G15: TOTAL | H15: =SUM(H11:H14) -> 150000 | I15: =SUM(I11:I14) -> 10000 | L15: 3 YRS | M15: =-PMT(G18/12,36,M12) -> 24503.702 | N15: =IF(M15>$M$10,"CANNOT BE","OK") -> CANNOT BE
L16: 2 YRS | M16: =-PMT(H18/12,24,M12) -> 35042.457 | N16: =IF(M16>$M$10,"CANNOT BE","OK") -> CANNOT BE
E17: TERM | F17: 4 YRS | G17: 3 YRS | H17: 2 YRS | I17: 1 YR | L17: 1 YR | M17: =-PMT(I18/12,12,M12) -> 66763.325 | N17: =IF(M17>$M$10,"CANNOT BE","OK") -> CANNOT BE
E18: INTEREST RATE (PER ANNUM) | F18: 0.12 | G18: 0.1 | H18: 0.1 | I18: 0.1
E19: MAXIMUM LOANABLE AMOUNT | F19: =ROUNDDOWN(-PV(F18/12,48,F37),-2) -> 759400 | G19: =ROUNDDOWN(-PV(G18/12,36,F37),-2) -> 619800 | H19: =ROUNDDOWN(-PV(H18/12,24,F37),-2) -> 433400 | I19: =ROUNDDOWN(-PV(I18/12,12,F37),-2) -> 227400 | L19: AMORT/MO | M19: 19997.91 | N19: =IF(M19>M10,"CANNOT BE","OK") -> OK
E20: MONTHLY AMORTIZATION | F20: =-PMT(F18/12,48,F19) -> 19997.915 | G20: =-PMT(G18/12,36,G19) -> 19999.203 | H20: =-PMT(H18/12,24,H19) -> 19999.211 | I20: =-PMT(I18/12,12,I19) -> 19992.073 | L20: TERM | M20: AMOUNT | N20: Net Proceeds
E21: ESTIMATED NET PROCEEDS | F21: =F19-F14-F31-H15 -> 595066.14 | G21: =G19-F14-G31-H15 -> 459598.01 | H21: =H19-F14-H31-H15 -> 276881.23 | I21: =I19-F14-I31-H15 -> 74683.41 | L21: 4 YRS | M21: =-PV(F18/12,48,M19) -> 759399.82 | N21: =(M21*0.97912334)-$F$14-H15 -> 593546.09
E22: NET TAKE HOME PAY | F22: =$F$13-F20+$F$15+$I$15 -> 20002.085 | G22: =$F$13-G20+$F$15+I15 -> 20000.797 | H22: =$F$13-H20+$F$15+I15 -> 20000.789 | I22: =$F$13-I20+$F$15+I15 -> 20007.927 | L22: 3 YRS | M22: =-PV(G18/12,36,M19) -> 619759.94 | N22: =(M22*0.97912334)-$F$14-H15 -> 456821.42
L23: 2 YRS | M23: =-PV(H18/12,24,M19) -> 433371.8 | N23: =(M23*0.97912334)-$F$14-H15 -> 274324.45
E24: THANK YOU FOR BANKING WITH DBP! | L24: 1 YR | M24: =-PV(I18/12,12,M19) -> 227466.4 | N24: =(M24*0.97912334)-$F$14-H15 -> 72717.657
I25: COPY RIGHTS: DBP CATBALOGAN
E26: COMPUTATIONS
E28: SERVICE FEE | F28: =IF(F19*1%<1500,F19*1%,1500) -> 1500 | G28: =IF(G19*1%<1500,G19*1%,1500) -> 1500 | H28: =IF(H19*1%<1500,H19*1%,1500) -> 1500 | I28: =IF(I19*1%<1500,I19*1%,1500) -> 1500
E29: DOC STAMPS | F29: =IF(F19<250000,0,F19/200) -> 3797 | G29: =IF(G19<250000,0,G19/200) -> 3099 | H29: =IF(H19<250000,0,H19/200) -> 2167 | I29: =IF(I19<250000,0,I19/200) -> 0
E30: MRI | F30: =(F19/1000)*G60 -> 9036.86 | G30: =G19*G59/1000 -> 5602.992 | H30: =H19*6.58/1000 -> 2851.772 | I30: =I19*G57/1000 -> 1216.59
E31: TOTAL FEES/CHARGES | F31: =SUM(F28:F30) -> 14333.86 | G31: =SUM(G28:G30) -> 10201.992 | H31: =SUM(H28:H30) -> 6518.772 | I31: =SUM(I28:I30) -> 2716.59
E33: NTHP ADD DBP LOAN AND OTHER LOANS | F33: =F13+F15+I15 -> 40000
E34: NTHP LESS 3.5K GAA | F34: =F33-3500 -> 36500
E35: IGIR | F35: =IF(F11>0,IF(F12<10000,20%,IF(F12<13000,30%,IF(F12<38000,35%,40%))),IF(F12<10000,10%,IF(F12<13000,25%,30%))) -> 0.4
E36: LOAN INSTALLMENT (LI) | F36: =F35*F12 -> 20000
E37: INSTALLMENT TO USE | F37: =IF(F34<F36,F34,F36) -> 20000
F41: IGIR TABLE - NEW
F42: Less than 10K | G42: 0.1
F43: From 10K to <13K | G43: 0.25
F44: From 13K to <18K | G44: 0.3
F45: From 18K to <38K | G45: 0.3
F46: From 38K and above | G46: 0.3
F48: IGIR TABLE - RENEWAL
F49: Less than 10K | G49: 0.2
F50: From 10K to <13K | G50: 0.3
F51: From 13K to <18K | G51: 0.35
F52: From 18K to <38K | G52: 0.35
F53: From 38K and above | G53: 0.4
...

Sheet GOV'T AGENCIES (2)
E8: YOUR FINANCING OPPORTUNITY WITH DBP
E9: INPUT DATA ON WHITE CELLS | I9: =NOW() -> 46084.283 | L9: GAA NTHP | M9: 4000 | P9: =DAY(EOMONTH(I9,0)) -> 31 | Q9: Month-end date | R9: LOAN EVALUATION GUIDE
G10: LOANS FOR TAKE-OUT | H10: BALANCE | I10: AMORT | L10: BPI days | M10: =$P$9-DAY(I9) -> 28 | N10: Prevailing Factor
E11: TYPE: [1] FOR RENEWAL/RE-AVAILMENT OR [0] FOR NEW | F11: 1 | G11: LOAN 1 | H11: 0 | I11: 3000 | L11: MAX AMORT: | M11: =F38 -> 20000 | N11: =IF(F37<F35,"BASED ON IGIR","BASED ON NTHP") -> BASED ON IGIR | R11: Min Loan Amount to Pay-off Everything | S11: =H15+F14+F32 -> 421421.59
E12: GROSS SALARY | F12: 50000 | G12: LOAN 2 | H12: 0 | I12: 0 | N12: Net Proceeds
E13: NET SALARY (OR NET TAKE HOME PAY) | F13: 20000 | G13: LOAN 3 | H13: 0 | I13: 0 | L13: LOAN AMOUNT | M13: 414334 | N13: =M13-F14-H15-F32 -> -7087.5933 | R13: ORIGINAL EFFECTIVE NTHP | S13: =F13-I15 -> 17000
E14: OUTSTANDING BALANCE OF EXISTING DBP LOAN | F14: 400000 | G14: LOAN 4 | H14: 0 | I14: 0 | L14: TERM | M14: AMORT/MO | N14: Remarks | R14: TERM | S14: AMORT/MO | T14: IGIR RATIO | U14: NTHP | V14: INC / DEC IN NTHP
E15: MONTHLY AMORTIZATION OF EXISTING DBP LOAN | F15: 17000 | G15: TOTAL | H15: =SUM(H11:H14) -> 0 | I15: =SUM(I11:I14) -> 3000 | L15: 4 YRS | M15: =-PMT(F18/12,48,M13) -> 10911.003 | N15: =IF(M15>$M$11,"CANNOT BE","OK") -> OK | R15: 4 YRS | S15: =-PMT(F18/12,48,M13) -> 10911.003 | T15: =S15/$F$12 -> 0.21822007 | U15: =$F$13+$I$15+$F$15-S15 -> 29088.997 | V15: =U15-($F$13-$I$15) -> 12088.997
L16: 3 YRS | M16: =-PMT(G18/12,36,M13) -> 13369.393 | N16: =IF(M16>$M$11,"CANNOT BE","OK") -> OK | R16: 3 YRS | S16: =-PMT(G18/12,36,M13) -> 13369.393 | T16: =S16/$F$12 -> 0.26738785 | U16: =$F$13+$I$15+$F$15-S16 -> 26630.607 | V16: =U16-($F$13-$I$15) -> 9630.6073
E17: TERM | F17: 4 YRS | G17: 3 YRS | H17: 2 YRS | I17: 1 YR | L17: 2 YRS | M17: =-PMT(H18/12,24,M13) -> 19119.412 | N17: =IF(M17>$M$11,"CANNOT BE","OK") -> OK | R17: 2 YRS | S17: =-PMT(H18/12,24,M13) -> 19119.412 | T17: =S17/$F$12 -> 0.38238824 | U17: =$F$13+$I$15+$F$15-S17 -> 20880.588 | V17: =U17-($F$13-$I$15) -> 3880.5881
E18: INTEREST RATE (PER ANNUM) | F18: 0.12 | G18: 0.1 | H18: 0.1 | I18: 0.1 | L18: 1 YR | M18: =-PMT(I18/12,12,M13) -> 36426.541 | N18: =IF(M18>$M$11,"CANNOT BE","OK") -> CANNOT BE | R18: 1 YR | S18: =-PMT(I18/12,12,M13) -> 36426.541 | T18: =S18/$F$12 -> 0.72853082 | U18: =$F$13+$I$15+$F$15-S18 -> 3573.4588 | V18: =U18-($F$13-$I$15) -> -13426.541
E19: MAXIMUM LOANABLE AMOUNT | F19: =ROUNDDOWN(-PV(F18/12,48,F38),-2) -> 759400 | G19: =ROUNDDOWN(-PV(G18/12,36,F38),-2) -> 619800 | H19: =ROUNDDOWN(-PV(H18/12,24,F38),-2) -> 433400 | I19: =ROUNDDOWN(-PV(I18/12,12,F38),-2) -> 227400
E20: MONTHLY AMORTIZATION | F20: =-PMT(F18/12,48,F19) -> 19997.915 | G20: =-PMT(G18/12,36,G19) -> 19999.203 | H20: =-PMT(H18/12,24,H19) -> 19999.211 | I20: =-PMT(I18/12,12,I19) -> 19992.073 | L20: AMORT/MO | M20: 19999.18 | N20: =IF(M20>M11,"CANNOT BE","OK") -> OK
E21: ESTIMATED NET PROCEEDS | F21: =F19-F14-F32-H15 -> 337978.41 | G21: =G19-F14-G32-H15 -> 204777.34 | H21: =H19-F14-H32-H15 -> 23510.339 | I21: =I19-F14-I32-H15 -> -177085.26 | L21: TERM | M21: AMOUNT | N21: Net Proceeds
E22: NET TAKE HOME PAY | F22: =$F$13-F20+$F$15+$I$15 -> 20002.085 | G22: =$F$13-G20+$F$15+I15 -> 20000.797 | H22: =$F$13-H20+$F$15+I15 -> 20000.789 | I22: =$F$13-I20+$F$15+I15 -> 20007.927 | L22: 4 YRS | M22: =-PV(F18/12,48,M20) -> 759448.05 | N22: =M22-$F$14-$H$15-F32 -> 338026.46
L23: 3 YRS | M23: =-PV(G18/12,36,M20) -> 619799.3 | N23: =M23-F14-H15-G32 -> 204776.64
E24: THANK YOU FOR BANKING WITH DBP! | L24: 2 YRS | M24: =-PV(H18/12,24,M20) -> 433399.33 | N24: =M24-F14-H15-H32 -> 23509.666
I25: COPY RIGHTS: DBP CATBALOGAN | L25: 1 YR | M25: =-PV(I18/12,12,M20) -> 227480.84 | N25: =M25-F14-H15-I32 -> -177004.42
E26: COMPUTATIONS
E28: SERVICE FEE | F28: =IF(F19*1%<1500,F19*1%,1500) -> 1500 | G28: =IF(G19*1%<1500,G19*1%,1500) -> 1500 | H28: =IF(H19*1%<1500,H19*1%,1500) -> 1500 | I28: =IF(I19*1%<1500,I19*1%,1500) -> 1500
E29: DOC STAMPS | F29: =IF(F19<250000,0,F19/200) -> 3797 | G29: =IF(G19<250000,0,G19/200) -> 3099 | H29: =IF(H19<250000,0,H19/200) -> 2167 | I29: =IF(I19<250000,0,I19/200) -> 0
E30: Max Broken Period Interest | F30: =F19*F18*$M$10/360 -> 7087.7333 | G30: =G19*G18*$M$10/360 -> 4820.6667 | H30: =H19*H18*$M$10/360 -> 3370.8889 | I30: =I19*I18*$M$10/360 -> 1768.6667
E31: MRI | F31: =(F19/1000)*G61 -> 9036.86 | G31: =G19*G60/1000 -> 5602.992 | H31: =H19*6.58/1000 -> 2851.772 | I31: =I19*G58/1000 -> 1216.59
E32: TOTAL FEES/CHARGES | F32: =SUM(F28:F31) -> 21421.593 | G32: =SUM(G28:G31) -> 15022.659 | H32: =SUM(H28:H31) -> 9889.6609 | I32: =SUM(I28:I31) -> 4485.2567
E34: NTHP ADD DBP LOAN AND OTHER LOANS | F34: =F13+F15+I15 -> 40000
E35: NTHP LESS GAA REQ | F35: =F34-$M$9 -> 36000
E36: IGIR | F36: =IF(F11>0,IF(F12<10000,20%,IF(F12<13000,30%,IF(F12<38000,35%,40%))),IF(F12<10000,10%,IF(F12<13000,25%,30%))) -> 0.4
E37: LOAN INSTALLMENT (LI) | F37: =F36*F12 -> 20000
E38: INSTALLMENT TO USE | F38: =IF(F35<F37,F35,F37) -> 20000
F42: IGIR TABLE - NEW
F43: Less than 10K | G43: 0.1
F44: From 10K to <13K | G44: 0.25
F45: From 13K to <18K | G45: 0.3
F46: From 18K to <38K | G46: 0.3
F47: From 38K and above | G47: 0.3
F49: IGIR TABLE - RENEWAL
F50: Less than 10K | G50: 0.2
F51: From 10K to <13K | G51: 0.3
F52: From 13K to <18K | G52: 0.35
F53: From 18K to <38K | G53: 0.35
...

Sheet WITH LOAN-TAKE-OUT
E8: HOW MUCH IS YOUR LOANABLE AMOUNT?
E9: INPUT DATA ON WHITE CELLS | N9: Prevailing Factor
G10: LOANS FOR TAKE-OUT | H10: BALANCE | I10: AMORT | L10: MAX AMORT: | M10: =F37 -> 20000 | N10: =IF(F36<F34,"BASED ON IGIR","BASED ON NTHP") -> BASED ON IGIR
E11: TYPE: [1] FOR RENEWAL/RE-AVAILMENT OR [0] FOR NEW | F11: 1 | G11: LOAN 1 | H11: 40000 | I11: 3000 | N11: Net Proceeds
E12: GROSS SALARY | F12: 50000 | G12: LOAN 2 | H12: 50000 | I12: 2000 | L12: LOAN AMOUNT | M12: 300000 | N12: =(0.97912334*M12-F14)-H15 -> 143737
E13: NET SALARY (OR NET TAKE HOME PAY) | F13: 30000 | G13: LOAN 3 | H13: 30000 | I13: 3000 | L13: TERM | M13: AMORT/MO | N13: Remarks
E14: OUTSTANDING BALANCE OF EXISTING DBP LOAN | F14: 0 | G14: LOAN 4 | H14: 30000 | I14: 2000 | L14: 4 YRS | M14: =-PMT(F18/12,48,M12) -> 8349.2245 | N14: =IF(M14>$M$10,"CANNOT BE","OK") -> OK
E15: MONTHLY AMORTIZATION OF EXISTING DBP LOAN | F15: 0 | G15: TOTAL | H15: =SUM(H11:H14) -> 150000 | I15: =SUM(I11:I14) -> 10000 | L15: 3 YRS | M15: =-PMT(G18/12,36,M12) -> 9964.2929 | N15: =IF(M15>$M$10,"CANNOT BE","OK") -> OK
L16: 2 YRS | M16: =-PMT(H18/12,24,M12) -> 14122.042 | N16: =IF(M16>$M$10,"CANNOT BE","OK") -> OK
E17: TERM | F17: 4 YRS | G17: 3 YRS | H17: 2 YRS | I17: 1 YR | L17: 1 YR | M17: =-PMT(I18/12,12,M12) -> 26654.637 | N17: =IF(M17>$M$10,"CANNOT BE","OK") -> CANNOT BE
E18: INTEREST RATE (PER ANNUM) | F18: 0.15 | G18: 0.12 | H18: 0.12 | I18: 0.12
E19: MAXIMUM LOANABLE AMOUNT | F19: =ROUNDDOWN(-PV(F18/12,48,F37),-2) -> 718600 | G19: =ROUNDDOWN(-PV(G18/12,36,F37),-2) -> 602100 | H19: =ROUNDDOWN(-PV(H18/12,24,F37),-2) -> 424800 | I19: =ROUNDDOWN(-PV(I18/12,12,F37),-2) -> 225100 | L19: AMORT/MO | M19: 8200 | N19: =IF(M19>M10,"CANNOT BE","OK") -> OK
E20: MONTHLY AMORTIZATION | F20: =-PMT(F18/12,48,F19) -> 19999.176 | G20: =-PMT(G18/12,36,G19) -> 19998.336 | H20: =-PMT(H18/12,24,H19) -> 19996.811 | I20: =-PMT(I18/12,12,I19) -> 19999.862 | L20: TERM | M20: AMOUNT | N20: Net Proceeds
E21: ESTIMATED NET PROCEEDS | F21: =F19-F14-F31-H15 -> 554955.66 | G21: =G19-F14-G31-H15 -> 442146.52 | H21: =H19-F14-H31-H15 -> 268380.82 | I21: =I19-F14-I31-H15 -> 72395.715 | L21: 4 YRS | M21: =-PV(F18/12,48,M19) -> 294638.14 | N21: =(M21*0.97912334)-$F$14-H15 -> 138487.08
E22: NET TAKE HOME PAY | F22: =$F$13-F20+$F$15+$I$15 -> 20000.824 | G22: =$F$13-G20+$F$15+I15 -> 20001.664 | H22: =$F$13-H20+$F$15+I15 -> 20003.189 | I22: =$F$13-I20+$F$15+I15 -> 20000.138 | L22: 3 YRS | M22: =-PV(G18/12,36,M19) -> 246881.54 | N22: =(M22*0.97912334)-$F$14-H15 -> 91727.479
L23: 2 YRS | M23: =-PV(H18/12,24,M19) -> 174195.78 | N23: =(M23*0.97912334)-$F$14-H15 -> 20559.15
E24: THANK YOU FOR BANKING WITH DBP! | L24: 1 YR | M24: =-PV(I18/12,12,M19) -> 92291.635 | N24: =(M24*0.97912334)-$F$14-H15 -> -59635.106
I25: COPY RIGHTS: DBP CATBALOGAN
E26: COMPUTATIONS
E28: SERVICE FEE | F28: =IF(F19*1%<1500,F19*1%,1500) -> 1500 | G28: =IF(G19*1%<1500,G19*1%,1500) -> 1500 | H28: =IF(H19*1%<1500,H19*1%,1500) -> 1500 | I28: =IF(I19*1%<1500,I19*1%,1500) -> 1500
E29: DOC STAMPS | F29: =IF(F19<250000,0,F19/200) -> 3593 | G29: =IF(G19<250000,0,G19/200) -> 3010.5 | H29: =IF(H19<250000,0,H19/200) -> 2124 | I29: =IF(I19<250000,0,I19/200) -> 0
E30: MRI | F30: =(F19/1000)*G60 -> 8551.34 | G30: =G19*G59/1000 -> 5442.984 | H30: =H19*6.58/1000 -> 2795.184 | I30: =I19*G57/1000 -> 1204.285
E31: TOTAL FEES/CHARGES | F31: =SUM(F28:F30) -> 13644.34 | G31: =SUM(G28:G30) -> 9953.484 | H31: =SUM(H28:H30) -> 6419.184 | I31: =SUM(I28:I30) -> 2704.285
E33: NTHP ADD DBP LOAN AND OTHER LOANS | F33: =F13+F15+I15 -> 40000
E34: NTHP LESS 3.5K GAA | F34: =F33-3500 -> 36500
E35: IGIR | F35: =IF(F11>0,IF(F12<10000,20%,IF(F12<13000,30%,IF(F12<38000,35%,40%))),IF(F12<10000,10%,IF(F12<13000,25%,30%))) -> 0.4
E36: LOAN INSTALLMENT (LI) | F36: =F35*F12 -> 20000
E37: INSTALLMENT TO USE | F37: =IF(F34<F36,F34,F36) -> 20000
F41: IGIR TABLE - NEW
F42: Less than 10K | G42: 0.1
F43: From 10K to <13K | G43: 0.25
F44: From 13K to <18K | G44: 0.3
F45: From 18K to <38K | G45: 0.3
F46: From 38K and above | G46: 0.3
F48: IGIR TABLE - RENEWAL
F49: Less than 10K | G49: 0.2
F50: From 10K to <13K | G50: 0.3
F51: From 13K to <18K | G51: 0.35
F52: From 18K to <38K | G52: 0.35
F53: From 38K and above | G53: 0.4
...

Sheet LOANABLE AMOUNT-REGULAR
E8: HOW MUCH IS YOUR LOANABLE AMOUNT?
N9: Prevailing Factor
L10: MAX AMORT: | M10: =F37 -> 9000 | N10: =IF(F36<F34,"BASED ON IGIR","BASED ON NTHP") -> BASED ON IGIR
E11: TYPE: [1] FOR RENEWAL/RE-AVAILMENT OR [0] FOR NEW | F11: 0 | N11: Net Proceeds
E12: GROSS SALARY | F12: 30000 | L12: LOAN AMOUNT | M12: 800000 | N12: =(0.97912334*M12-F14) -> 783298.67
E13: NET SALARY (OR NET TAKE HOME PAY) | F13: 25000 | L13: TERM | M13: AMORT/MO | N13: Remarks
E14: OUTSTANDING BALANCE OF EXISTING DBP LOAN | F14: 0 | L14: 4 YRS | M14: =-PMT(F18/12,48,M12) -> 22264.599 | N14: =IF(M14>$M$10,"CANNOT BE","OK") -> CANNOT BE
E15: MONTHLY AMORTIZATION OF EXISTING DBP LOAN | F15: 0 | L15: 3 YRS | M15: =-PMT(G18/12,36,M12) -> 26571.448 | N15: =IF(M15>$M$10,"CANNOT BE","OK") -> CANNOT BE
L16: 2 YRS | M16: =-PMT(H18/12,24,M12) -> 37658.778 | N16: =IF(M16>$M$10,"CANNOT BE","OK") -> CANNOT BE
E17: TERM | F17: 4 YRS | G17: 3 YRS | H17: 2 YRS | I17: 1 YR | L17: 1 YR | M17: =-PMT(I18/12,12,M12) -> 71079.031 | N17: =IF(M17>$M$10,"CANNOT BE","OK") -> CANNOT BE
E18: INTEREST RATE (PER ANNUM) | F18: 0.15 | G18: 0.12 | H18: 0.12 | I18: 0.12
E19: MAXIMUM LOANABLE AMOUNT | F19: =ROUNDDOWN(-PV(F18/12,48,F37),-2) -> 323300 | G19: =ROUNDDOWN(-PV(G18/12,36,F37),-2) -> 270900 | H19: =ROUNDDOWN(-PV(H18/12,24,F37),-2) -> 191100 | I19: =ROUNDDOWN(-PV(I18/12,12,F37),-2) -> 101200 | L19: AMORT/MO | M19: 15000
E20: MONTHLY AMORTIZATION | F20: =-PMT(F18/12,48,F19) -> 8997.6809 | G20: =-PMT(G18/12,36,G19) -> 8997.7565 | H20: =-PMT(H18/12,24,H19) -> 8995.7405 | I20: =-PMT(I18/12,12,I19) -> 8991.4974 | L20: TERM | M20: AMOUNT | N20: Net Proceeds
E21: ESTIMATED NET PROCEEDS | F21: =F19-F14-F31 -> 316336.23 | G21: =G19-F14-G31 -> 265596.56 | H21: =H19-F14-H31 -> 188342.56 | I21: =I19-F14-I31 -> 99646.58 | L21: 4 YRS | M21: =-PV(F18/12,48,M19) -> 538972.21 | N21: =(M21*0.97912334)-$F$14 -> 527720.27
E22: NET TAKE HOME PAY | F22: =$F$13-F20+$F$15 -> 16002.319 | G22: =$F$13-G20+$F$15 -> 16002.243 | H22: =$F$13-H20+$F$15 -> 16004.259 | I22: =$F$13-I20+$F$15 -> 16008.503 | L22: 3 YRS | M22: =-PV(G18/12,36,M19) -> 451612.58 | N22: =(M22*0.97912334)-$F$14 -> 442184.41
L23: 2 YRS | M23: =-PV(H18/12,24,M19) -> 318650.81 | N23: =(M23*0.97912334)-$F$14 -> 311998.44
E24: THANK YOU FOR BANKING WITH DBP! | L24: 1 YR | M24: =-PV(I18/12,12,M19) -> 168826.16 | N24: =(M24*0.97912334)-$F$14 -> 165301.64
I25: COPY RIGHTS: DBP CATBALOGAN
E26: COMPUTATIONS
E28: SERVICE FEE | F28: =IF(F19*1%<1500,F19*1%,1500) -> 1500 | G28: =IF(G19*1%<1500,G19*1%,1500) -> 1500 | H28: =IF(H19*1%<1500,H19*1%,1500) -> 1500 | I28: =IF(I19*1%<1500,I19*1%,1500) -> 1012
E29: DOC STAMPS | F29: =IF(F19<250000,0,F19/200) -> 1616.5 | G29: =IF(G19<250000,0,G19/200) -> 1354.5 | H29: =IF(H19<250000,0,H19/200) -> 0 | I29: =IF(I19<250000,0,I19/200) -> 0
E30: MRI | F30: =(F19/1000)*G60 -> 3847.27 | G30: =G19*G59/1000 -> 2448.936 | H30: =H19*6.58/1000 -> 1257.438 | I30: =I19*G57/1000 -> 541.42
E31: TOTAL FEES/CHARGES | F31: =SUM(F28:F30) -> 6963.77 | G31: =SUM(G28:G30) -> 5303.436 | H31: =SUM(H28:H30) -> 2757.438 | I31: =SUM(I28:I30) -> 1553.42
E33: NTHP ADD DBP LOAN | F33: =F13+F15 -> 25000
E34: NTHP LESS 3.5K GAA | F34: =F33-3500 -> 21500
E35: IGIR | F35: =IF(F11>0,IF(F12<10000,20%,IF(F12<13000,30%,IF(F12<38000,35%,40%))),IF(F12<10000,10%,IF(F12<13000,25%,30%))) -> 0.3
E36: LOAN INSTALLMENT (LI) | F36: =F35*F12 -> 9000
E37: INSTALLMENT TO USE | F37: =IF(F34<F36,F34,F36) -> 9000
F41: IGIR TABLE - NEW
F42: Less than 10K | G42: 0.1
F43: From 10K to <13K | G43: 0.25
F44: From 13K to <18K | G44: 0.3
F45: From 18K to <38K | G45: 0.3
F46: From 38K and above | G46: 0.3
F48: IGIR TABLE - RENEWAL
F49: Less than 10K | G49: 0.2
F50: From 10K to <13K | G50: 0.3
F51: From 13K to <18K | G51: 0.35
F52: From 18K to <38K | G52: 0.35
F53: From 38K and above | G53: 0.4
...

Sheet LOANABLE AMOUNT- DAR
E8: HOW MUCH IS YOUR LOANABLE AMOUNT?
E11: ---FOR DAR ONLY---
E12: GROSS SALARY | F12: 50000
E13: NET SALARY (OR NET TAKE HOME PAY) | F13: 40000
E14: OUTSTANDING BALANCE OF EXISTING DBP LOAN | F14: 0
E15: MONTHLY AMORTIZATION OF EXISTING DBP LOAN | F15: 0
E17: TERM | F17: 4 YRS | G17: 3 YRS | H17: 2 YRS | I17: 1 YR
E18: INTEREST RATE (PER ANNUM) | F18: 0.12 | G18: 0.1 | H18: 0.1 | I18: 0.1
E19: MAXIMUM LOANABLE AMOUNT | F19: =ROUNDDOWN(-PV(F18/12,48,F37),-2) -> 569600 | G19: =ROUNDDOWN(-PV(G18/12,36,F37),-2) -> 464800 | H19: =ROUNDDOWN(-PV(H18/12,24,F37),-2) -> 325000 | I19: =ROUNDDOWN(-PV(I18/12,12,F37),-2) -> 170600
E20: MONTHLY AMORTIZATION | F20: =-PMT(F18/12,48,F19) -> 14999.753 | G20: =-PMT(G18/12,36,G19) -> 14997.789 | H20: =-PMT(H18/12,24,H19) -> 14997.101 | I20: =-PMT(I18/12,12,I19) -> 14998.45
E21: ESTIMATED NET PROCEEDS | F21: =F19-F14-F31 -> 558473.76 | G21: =G19-F14-G31 -> 456774.21 | H21: =H19-F14-H31 -> 319736.5 | I21: =I19-F14-I31 -> 168187.29
E22: NET TAKE HOME PAY | F22: =$F$13-F20+$F$15 -> 25000.247 | G22: =$F$13-G20+$F$15 -> 25002.211 | H22: =$F$13-H20+$F$15 -> 25002.899 | I22: =$F$13-I20+$F$15 -> 25001.55
E24: THANK YOU FOR BANKING WITH DBP!
I25: COPY RIGHTS: DBP CATBALOGAN
E26: COMPUTATIONS
E28: SERVICE FEE | F28: =IF(F19*1%<1500,F19*1%,1500) -> 1500 | G28: =IF(G19*1%<1500,G19*1%,1500) -> 1500 | H28: =IF(H19*1%<1500,H19*1%,1500) -> 1500 | I28: =IF(I19*1%<1500,I19*1%,1500) -> 1500
E29: DOC STAMPS | F29: =IF(F19<250000,0,F19/200) -> 2848 | G29: =IF(G19<250000,0,G19/200) -> 2324 | H29: =IF(H19<250000,0,H19/200) -> 1625 | I29: =IF(I19<250000,0,I19/200) -> 0
E30: MRI | F30: =(F19/1000)*G60 -> 6778.24 | G30: =G19*G59/1000 -> 4201.792 | H30: =H19*6.58/1000 -> 2138.5 | I30: =I19*G57/1000 -> 912.71
E31: TOTAL FEES/CHARGES | F31: =SUM(F28:F30) -> 11126.24 | G31: =SUM(G28:G30) -> 8025.792 | H31: =SUM(H28:H30) -> 5263.5 | I31: =SUM(I28:I30) -> 2412.71
E33: NTHP ADD DBP LOAN | F33: =F13+F15 -> 40000
E34: NTHP LESS 3.5K GAA | F34: =F33-3500 -> 36500
E35: IGIR | F35: =IF(F15>0,IF(F12<10000,20%,IF(F12<13000,30%,IF(F12<38000,35%,40%))),IF(F12<10000,10%,IF(F12<13000,25%,30%))) -> 0.3
E36: LOAN INSTALLMENT (LI) | F36: =F35*F12 -> 15000
E37: INSTALLMENT TO USE | F37: =IF(F34<F36,F34,F36) -> 15000
F41: IGIR TABLE - NEW
F42: Less than 10K | G42: 0.1
F43: From 10K to <13K | G43: 0.25
F44: From 13K to <18K | G44: 0.3
F45: From 18K to <38K | G45: 0.3
F46: From 38K and above | G46: 0.3
F48: IGIR TABLE - RENEWAL
F49: Less than 10K | G49: 0.2
F50: From 10K to <13K | G50: 0.3
F51: From 13K to <18K | G51: 0.35
F52: From 18K to <38K | G52: 0.35
F53: From 38K and above | G53: 0.4
F56: MRI TARIFF (per 1000.00)
F57: 12 MOS | G57: 5.35
F58: 24 MOS | G58: 6.58
F59: 36 MOS | G59: 9.04
...

Sheet Signatories
B4: PLEASE PROVIDE INFO ON THE FF:
B8: NAME OF SIGNATORIES
B9: Name of RO | C9: JANICE B. SOLAYAO
B10: Name of BOO | C10: AM IRISH MAE N. CREER
B11: Name of Manager | C11: SM HELBERT ANTOINE A. ACHAY
B13: Branch | C13: CATBALOGAN
B14: Address | C14: CATBALOGAN CITY, SAMAR
B15: RMC | C15: EASTERN VISAYAS

Sheet INPUT FIELDS
C2: PROVINCE OF SAMAR RSLP TEMPLATE
C4: BORROWER'S DATA SHEET
D5: 1 | AV5: 2 | AX5: 3 | AZ5: 4 | BB5: 5 | BD5: 6 | BF5: 7 | BH5: 8 | BJ5: 9 | BL5: 10 | BN5: 11 | BP5: 12 | BR5: 13 | BT5: 14 | BV5: 15 | BX5: 16 | BZ5: 17 | CB5: 18 | CD5: 19 | CF5: 20
C6: OT NO AND DATE | D6: OT N0. 15-005 DATED APRIL 7, 2015
C7: SURNAME | D7: RABADAM | AV7: LEJAS | AX7: NUNEZ | AZ7: LIMA | BB7: ALEGRIA | BD7: GACELOS | BF7: GONZALES | BH7: MAYOR | BJ7: YBOA | BL7: GONZALES | BN7: ARCALES | BP7: GACELOS | BR7: TONELETE | BT7: GABON
C8: FIRST NAME | D8: MARIA EMY | AV8: ALLAN | AX8: JOSE JR | AZ8: NESTOR | BB8: MARCIANO JR | BD8: MANOLITO | BF8: LEONILA | BH8: CHONA | BJ8: JONAS | BL8: RUBIA | BN8: DOMINGO JR | BP8: REBECCA | BR8: NARCISA | BT8: MA WINONA
C9: MIDDLE NAME | D9: TAN | AV9: GULFERIC | AX9: ADESAS | AZ9: PELENO | BB9: HERNANDEZ | BD9: ABARRACOSO | BF9: HILONGO | BH9: BRANZUELA | BJ9: ABELIDO | BL9: ABARCAR | BN9: JADLOC | BP9: TILLES | BR9: CAMUIN | BT9: CON UI
C10: NAME OF SPOUSE | D10: ARNEL B RABADAM | AV10: MARIAN DAGANZO LEJAS | AX10: ERLINDA BACUETES NUNEZ | AZ10: MARY GEN ISANAN LIMA | BB10: MARILYN SOLAYAO ALEGRIA | BD10: CHERIE N GACELOS | BH10: VENG JAYCO B MAYOR | BJ10: NANCY ALBOS YBOA | BL10: NELSON VILLANUEVA GONZALES | BR10: ANTONIO DETALO TONELETE | BT10: ALEJANDRO CUNA GABON
C11: ADDRESS | D11: 202 CURRY AVENUE CATBALOGAN CITY SAMAR | AV11: PUROK 1 BRGY CANLAPWAS CATBALOGAN CITY SAMAR | AX11: 352 RIZAL AVENUE BRGY 12 CATBALOGAN CITY SAMAR | AZ11: PATONG STREET BRGY GUINSORONGAN CATBALOGAN CITY | BB11: P2 BRGY JIA AN JIABONG SAMAR | BD11: BRGY RAWIS HINABANGAN SAMAR | BF11: BRGY SAN JOSE ALMAGRO WESTERN SAMAR | BH11: BRGY PANJOBJOBAN ALMAGRO SAMAR | BJ11: 5TH ST COR BANOYO ST BRGY 10 CATBALOGAN CITY SAMAR | BL11: NO 20 B 2 LOT 8 BLISS CANLAPWAS CATBALOGAN CITY | BN11: 491 PUROK 3 BRGY MERCEDES CATBALOGAN CITY | BP11: 117 P 2 BRGY MAULONG CATBALOGAN CITY SAMAR | BR11: 270 BRGY MAULONG CATBALOGAN CITY SAMAR | BT11: 451 GABON BLVD BRGY 3 PARANAS WRIGHT SAMAR
C12: TIN | D12: 943994147 | AV12: 273165815 | AX12: 184693732 | AZ12: 130157835 | BB12: 905838005 | BD12: 400532413 | BF12: 129842327 | BH12: 947543937 | BJ12: 174344327 | BL12: 166545733 | BN12: 914894035 | BP12: 131439004 | BR12: 133458617 | BT12: 178650362
C13: BIRTHDATE | D13: 29144 | AV13: 30469 | AX13: 112566 | AZ13: 20219 | BB13: 26900 | BD13: 28260 | BF13: 20852 | BH13: 24599 | BJ13: 25868 | BL13: 22656 | BN13: 24098 | BP13: 19920 | BR13: 21917 | BT13: 25812
C14: DATE PERMANENT | D14: 39218 | AV14: 40525 | AX14: 34541 | AZ14: 31048 | BB14: 36297 | BD14: 40252 | BF14: 30376 | BH14: 39114 | BJ14: 35492 | BL14: 34319 | BN14: 35506 | BP14: 29859 | BR14: 29692 | BT14: 37097
C15: AGENCY/EMPLOYER | D15: PROVINCE OF SAMAR1 | AV15: PROVINCE OF SAMAR2 | AX15: PROVINCE OF SAMAR3 | AZ15: PROVINCE OF SAMAR4 | BB15: PROVINCE OF SAMAR5 | BD15: PROVINCE OF SAMAR6 | BF15: PROVINCE OF SAMAR7 | BH15: PROVINCE OF SAMAR4 | BJ15: PROVINCE OF SAMAR9 | BL15: PROVINCE OF SAMAR10 | BN15: PROVINCE OF SAMAR11 | BP15: PROVINCE OF SAMAR12 | BR15: PROVINCE OF SAMAR13 | BT15: PROVINCE OF SAMAR14
C16: OFFICE | D16: PROVINCIAL TREASURER OFFICE | AV16: PROVINCIAL ENGINEERING OFFICE | AX16: PROVINCIAL AGRICULTURE OFFICE | AZ16: PROVINCIAL WARDENS OFFICE | BB16: PROVINCIAL WARDENS OFFICE | BD16: PROVINCIAL HEALTH OFFICE | BN16: PROVINCIAL AGRICULTURE OFFICE | BR16: PROVINCIAL SANGGUNIANG PANLALAWIGAN
C17: POSITION | D17: ADMIN AIDE I | AV17: CM CAPATAZ | AX17: DRAFTSMAN I | AZ17: PRISON GUARD I | BB17: ADMIN AIDE III | BD17: DRIVER I | BF17: DENTIST II | BH17: DENTAL AIDE | BJ17: ADMIN AIDE VI | BL17: LABORATORY AIDE I | BN17: AGRICULTURAL TECHNICIAN II | BP17: AGRICULTURAL TECHNOLOGIST I | BR17: BOARD SECRETARY I | BT17: COMPUTER MAINTENANCE TECHNICIAN
C18: BASIC PAY | D18: 38000 | AV18: 12139 | AX18: 13853 | AZ18: 12886 | BB18: 10931 | BD18: 10505 | BF18: 31339 | BH18: 11405 | BJ18: 13580 | BL18: 10373 | BN18: 15768.87 | BP18: 18135 | BR18: 23979 | BT18: 19495
C19: ACA/PERA/RATA/OTHERS | D19: 2000 | AV19: 2000 | AX19: 2000 | AZ19: 2000 | BB19: 2000 | BD19: 3650 | BF19: 3650 | BH19: 3650 | BJ19: 2000 | BL19: 3650 | BN19: 2000 | BP19: 2000 | BR19: 2000 | BT19: 2000
C20: TOTAL DEDUCTIONS PER NTHP | D20: 26000 | AV20: 6939.36 | AX20: 9753.9 | AZ20: 10386 | BB20: 7761 | BD20: 2357.99 | BF20: 21547.08 | BH20: 8448.62 | BJ20: 10473.62 | BL20: 7735.27 | BN20: 12313.58 | BP20: 14037.39 | BR20: 16345.01 | BT20: 8580.2
C21: EXISTING DBP LOAN AMORT | D21: 5000 | AV21: 0 | AX21: 3714.69 | AZ21: 3453.19 | BB21: 2999.23 | BD21: 0 | BF21: 8404.99 | BH21: 3057.58 | BJ21: 3640.94 | BL21: 2752.49 | BN21: 4207.52 | BP21: 4652.09 | BR21: 6583.07 | BT21: 5176.43
C23: APPLICATION NO | D23: 15-0070 | AV23: 15-0070 | AX23: 15-0070 | AZ23: 15-0080 | CF23: 15-0070
C24: DATE FILED | D24: 42094 | AV24: 42094 | AX24: 42094 | AZ24: 42094 | BB24: 42100 | BD24: 42101 | BF24: 42100 | BH24: 42100 | BJ24: 42100 | BL24: 42100 | BN24: 42100 | BP24: 42101 | BR24: 42100 | BT24: 42100
C25: DATE EXECUTED: SPA NOTARIZATION DATE | D25: 42081 | AV25: 34409 | AX25: 42095 | AZ25: 42087 | BB25: 42095 | BD25: 42101 | BF25: 42100 | BH25: 42100 | BJ25: 42093 | BL25: 42093 | BN25: 42100 | BP25: 42100 | BR25: 42093 | BT25: 42093
C26: CERTIFICATION DATE: AS PERMANENT EMPLOYEE | D26: 42081 | AV26: 42097 | AX26: 42095 | AZ26: 42093 | BB26: 42100 | BD26: 42101 | BF26: 42095 | BH26: 42100 | BJ26: 42090 | BL26: 42100 | BN26: 42095 | BP26: 42100 | BR26: 42087 | BT26: 42086
C27: CERTIFICATION DATE: NO PENDING ADMIN CASE | D27: 42081 | AV27: 42135 | AX27: 42093 | AZ27: 42087 | BB27: 42090 | BD27: =BD26 -> 42101 | BF27: =BF26 -> 42095 | BH27: 42095 | BJ27: 42093 | BL27: 42095 | BM27: 0 | BN27: 42093 | BP27: 42093 | BR27: 42087 | BT27: =BT26 -> 42086 | BV27: =BV26 -> 0 | BX27: =BX26 -> 0 | BZ27: =BZ26 -> 0 | CB27: =CB26 -> 0 | CD27: =CD26 -> 0 | CF27: =CF26 -> 0
C28: CERTIFICATION DATE: LEAVE CREDITS | D28: 42081 | AV28: 42463 | AX28: 42095 | AZ28: 42087 | BB28: =BB26 -> 42100 | BD28: =BD26 -> 42101 | BF28: =BF26 -> 42095 | BH28: 42095 | BJ28: =BJ26 -> 42090 | BL28: 42095 | BN28: 42093 | BP28: 42093 | BR28: =BR26 -> 42087 | BT28: =BT26 -> 42086 | BV28: =BV26 -> 0 | BX28: =BX26 -> 0 | BZ28: =BZ26 -> 0 | CB28: =CB26 -> 0 | CD28: =CD26 -> 0 | CF28: =CF26 -> 0
C29: DATE ISSUED: SERVICE RECORD | D29: 42081 | AV29: 42463 | AX29: 42095 | AZ29: 42087 | BB29: 42089 | BD29: 42101 | BF29: 42095 | BH29: 42095 | BJ29: 42093 | BL29: 42095 | BN29: 42093 | BP29: 42100 | BR29: 42086 | BT29: 42088
C30: DATE ISSUED: CERT OF NET TAKE HOME PAY | D30: 42081 | AV30: 42463 | AX30: 42095 | AZ30: 42087 | BB30: 42089 | BD30: 42101 | BF30: 42095 | BH30: 42094 | BJ30: 42090 | BL30: 42094 | BN30: 42095 | BP30: 42093 | BR30: 42087 | BT30: 42086
C31: DATE SWORN: OATH OF OFFICE (ELECTIVE OFF'L) | D31: NA | AV31: NA | AX31: NA | AZ31: NA | BB31: NA | BD31: NA | BF31: NA | BH31: NA | BJ31: NA | BL31: NA | BN31: NA | BP31: NA | BR31: NA | BT31: NA
C32: BIR FORM 2316/ITR | D32: 2014 | AV32: 2014 | AX32: 2014 | AZ32: 2014 | BB32: 2014 | BD32: 2014 | BF32: 2014 | BH32: 2014 | BJ32: 2014 | BL32: 2014 | BN32: 2014 | BP32: 2014 | BR32: 2014 | BT32: 2014
C33: DATE ISSUED: NFIS CHECKING | D33: - | AV33: - | AX33: - | AZ33: - | CF33: -
D35: 1 | AL35: 5 | AM35: 5 | AN35: 6 | AO35: 7 | AP35: 8 | AQ35: 9 | AR35: 10 | AS35: 11 | AT35: 12 | AV35: 2 | AX35: 3 | AZ35: 4 | BB35: 5 | BD35: 6 | BF35: 7 | BH35: 8 | BJ35: 9 | BL35: 10 | BN35: 11 | BP35: 12 | BR35: 13 | BT35: 14 | BV35: 15 | BX35: 16 | BZ35: 17 | CB35: 18 | CD35: 19 | CF35: 20
D36: NAME | E36: BIRTHDATE | F36: DATE PERMANENT | G36: AGE | H36: YEARS IN SERVICE | I36: POSITION | J36: BASIC SALARY | K36: ACA/PERA/OTHERS | L36: GROSS INCOME | M36: TOTAL DEDUCTIONS PER NTHP | N36: LESS: EXISTING DBP LOANS | O36: IGIR % | P36: MAX LI | Q36: ADD: NEW AMORT | R36: NEW TOTAL DEDUCTIONS | S36: MONTHLY NTHP | T36: TYPE OF LOAN (NEW/RENEWAL) | U36: MAX LOAN AMOUNT | V36: AMOUNT OF LOAN | W36: INTEREST RATE | X36: TERM OF LOAN | Z36: Application No. | AA36: Date Filed | AB36: Date Executed | AC36: Date Issued | AD36: Date Issued | AE36: Date Issued | AF36: Date Issued | AG36: Date Issued | AH36: Date Sworn | AI36: For Year | AJ36: Date Issued | AL36: IB_FNAM | AM36: IB_MNAM | AN36: IB_LNAM | AO36: IB_SPOUSE | AP36: IB_ADDR1 | AQ36: IB_TAN | AR36: IB_BIRTH | AS36: RECKEY | AT36: IB_BANKCD
C37: 1 | D37: =CONCATENATE(D7,", ",D8," ",D9) -> RABADAM, MARIA EMY TAN | E37: =D13 -> 29144 | F37: =D14 -> 39218 | G37: =IF(E37>0,ROUNDDOWN((NOW()-E37)/365,0),0) -> 46 | H37: =IF(F37>0,ROUNDDOWN((NOW()-F37)/365,0),0) -> 18 | I37: =D17 -> ADMIN AIDE I | J37: =D18 -> 38000 | K37: =D19 -> 2000 | L37: =J37+K37 -> 40000 | M37: =D20 -> 26000 | N37: =D21 -> 5000 | O37: =IF(L37<10000,10%,IF(L37<13000,25%,30%)) -> 0.3 | P37: =L37*O37 -> 12000 | Q37: =-PMT(W37/12,X37,V37) -> 6392.3145 | R37: =M37-N37+Q37 -> 27392.315 | S37: =J37+K37-R37 -> 12607.685 | T37: =IF(N37>0,"RENEWAL","NEW") -> RENEWAL | U37: =-PV(W37/12,X37,P37) -> 134599.13 | V37: ='COMPUTATION SHEET'!AA24 -> 71700 | W37: =IF(X37>36,15.81%,12.651%) -> 0.12651 | X37: ='COMPUTATION SHEET'!AC24 -> 12 | Y37: =C37 -> 1 | Z37: =D23 -> 15-0070 | AA37: =$D24 -> 42094 | AB37: =$D25 -> 42081 | AC37: =$D26 -> 42081 | AD37: =$D27 -> 42081 | AE37: =$D28 -> 42081 | AF37: =$D29 -> 42081 | AG37: =$D30 -> 42081 | AH37: =$D31 -> NA | AI37: =$D32 -> 2014 | AJ37: =$D33 -> - | AL37: =$D7 -> RABADAM | AM37: =$D8 -> MARIA EMY | AN37: =$D9 -> TAN | AO37: =$D10 -> ARNEL B RABADAM | AP37: =$D11 -> 202 CURRY AVENUE CATBALOGAN CITY SAMAR | AQ37: =$D12 -> 943994147 | AR37: =$D13 -> 29144 | AS37: =$D15 -> PROVINCE OF SAMAR1 | AT37: DBP | AV37: =CONCATENATE(AV7,", ",AV8," ",AV9) -> LEJAS, ALLAN GULFERIC | AX37: =CONCATENATE(AX7,", ",AX8," ",AX9) -> NUNEZ, JOSE JR ADESAS | AZ37: =CONCATENATE(AZ7,", ",AZ8," ",AZ9) -> LIMA, NESTOR PELENO | BB37: =CONCATENATE(BB7,", ",BB8," ",BB9) -> ALEGRIA, MARCIANO JR HERNANDEZ | BD37: =CONCATENATE(BD7,", ",BD8," ",BD9) -> GACELOS, MANOLITO ABARRACOSO | BF37: =CONCATENATE(BF7,", ",BF8," ",BF9) -> GONZALES, LEONILA HILONGO | BH37: =CONCATENATE(BH7,", ",BH8," ",BH9) -> MAYOR, CHONA BRANZUELA | BJ37: =CONCATENATE(BJ7,", ",BJ8," ",BJ9) -> YBOA, JONAS ABELIDO | BL37: =CONCATENATE(BL7,", ",BL8," ",BL9) -> GONZALES, RUBIA ABARCAR | BM37: 1 | BN37: =CONCATENATE(BN7,", ",BN8," ",BN9) -> ARCALES, DOMINGO JR JADLOC | BP37: =CONCATENATE(BP7,", ",BP8," ",BP9) -> GACELOS, REBECCA TILLES | BR37: =CONCATENATE(BR7,", ",BR8," ",BR9) -> TONELETE, NARCISA CAMUIN | BT37: =CONCATENATE(BT7,", ",BT8," ",BT9) -> GABON, MA WINONA CON UI | BV37: =CONCATENATE(BV7,", ",BV8," ",BV9) -> , | BX37: =CONCATENATE(BX7,", ",BX8," ",BX9) -> , | BZ37: =CONCATENATE(BZ7,", ",BZ8," ",BZ9) -> , | CB37: =CONCATENATE(CB7,", ",CB8," ",CB9) -> , | CD37: =CONCATENATE(CD7,", ",CD8," ",CD9) -> , | CF37: =CONCATENATE(CF7,", ",CF8," ",CF9) -> ,
Q38: =-PMT(W38/12,X38,V38) -> 0 | R38: =M38-N38+Q38 -> 0 | S38: =J38+K38-R38 -> 0 | T38: RENEWAL | U38: =-PV(W38/12,X38,P38) -> 0 | V38: ='COMPUTATION SHEET'!AA25 -> 0 | W38: =IF(X38>36,15.81%,12.651%) -> 0.1581 | X38: 49 | Y38: =C38 -> 0
C39: 2 | D39: =AV37 -> LEJAS, ALLAN GULFERIC | E39: =AV13 -> 30469 | F39: =AV14 -> 40525 | G39: =IF(E39>0,ROUNDDOWN((NOW()-E39)/365,0),0) -> 42 | H39: =IF(F39>0,ROUNDDOWN((NOW()-F39)/365,0),0) -> 15 | I39: =AV17 -> CM CAPATAZ | J39: =AV18 -> 12139 | K39: =AV19 -> 2000 | L39: =J39+K39 -> 14139 | M39: =AV20 -> 6939.36 | N39: =AV21 -> 0 | O39: =IF(L39<10000,10%,IF(L39<13000,25%,30%)) -> 0.3 | P39: =L39*O39 -> 4241.7 | Q39: =-PMT(W39/12,X39,V39) -> 3191.4665 | R39: =M39-N39+Q39 -> 10130.826 | S39: =J39+K39-R39 -> 4008.1735 | T39: =IF(N39>0,"RENEWAL","NEW") -> NEW | U39: =-PV(W39/12,X39,P39) -> 150185.53 | V39: ='COMPUTATION SHEET'!AA26 -> 113000 | W39: =IF(X39>36,15.81%,12.651%) -> 0.1581 | X39: ='COMPUTATION SHEET'!AC26 -> 48 | Y39: =C39 -> 2 | Z39: =AV23 -> 15-0070 | AA39: =$AV24 -> 42094 | AB39: =$AV25 -> 34409 | AC39: =$AV26 -> 42097 | AD39: =$AV27 -> 42135 | AE39: =$AV28 -> 42463 | AF39: =$AV29 -> 42463 | AG39: =$AV30 -> 42463 | AH39: =$AV31 -> NA | AI39: =$AV32 -> 2014 | AJ39: =$AV33 -> - | AL39: =$AV7 -> LEJAS | AM39: =$AV8 -> ALLAN | AN39: =$AV9 -> GULFERIC | AO39: =$AV10 -> MARIAN DAGANZO LEJAS | AP39: =$AV11 -> PUROK 1 BRGY CANLAPWAS CATBALOGAN CITY SAMAR | AQ39: =$AV12 -> 273165815 | AR39: =$AV13 -> 30469 | AS39: =$AV15 -> PROVINCE OF SAMAR2 | AT39: DBP
G40: =ROUNDDOWN((NOW()-E40)/365,0) -> 126 | H40: =ROUNDDOWN((NOW()-F40)/365,0) -> 126 | L40: =J40+K40 -> 0 | O40: =IF(L40<10000,10%,IF(L40<13000,25%,30%)) -> 0.1 | P40: =L40*O40 -> 0 | Q40: =-PMT(W40/12,X40,V40) -> #NUM! | R40: =M40-N40+Q40 -> #NUM! | S40: =J40+K40-R40 -> #NUM! | T40: =IF(N40>0,"RENEWAL","NEW") -> NEW | U40: =-PV(W40/12,X40,P40) -> 0 | V40: ='COMPUTATION SHEET'!AA27 -> 0 | W40: =IF(X40>36,15.81%,12.651%) -> 0.12651 | X40: ='COMPUTATION SHEET'!AC27 -> 0 | Y40: =C40 -> 0 | AT40: DBP
C41: 3 | D41: =AX37 -> NUNEZ, JOSE JR ADESAS | E41: =AX13 -> 112566 | F41: =AX14 -> 34541 | G41: =IF(E41>0,ROUNDDOWN((NOW()-E41)/365,0),0) -> -182 | H41: =IF(F41>0,ROUNDDOWN((NOW()-F41)/365,0),0) -> 31 | I41: =AX17 -> DRAFTSMAN I | J41: =AX18 -> 13853 | K41: =AX19 -> 2000 | L41: =J41+K41 -> 15853 | M41: =AX20 -> 9753.9 | N41: =AX21 -> 3714.69 | O41: =IF(L41<10000,10%,IF(L41<13000,25%,30%)) -> 0.3 | P41: =L41*O41 -> 4755.9 | Q41: =-PMT(W41/12,X41,V41) -> 5546.9382 | R41: =M41-N41+Q41 -> 11586.148 | S41: =J41+K41-R41 -> 4266.8518 | T41: =IF(N41>0,"RENEWAL","NEW") -> RENEWAL | U41: =-PV(W41/12,X41,P41) -> 168391.77 | V41: ='COMPUTATION SHEET'!AA28 -> 196400 | W41: =IF(X41>36,15.81%,12.651%) -> 0.1581 | X41: ='COMPUTATION SHEET'!AC28 -> 48 | Y41: =C41 -> 3 | Z41: =AX23 -> 15-0070 | AA41: =$AX24 -> 42094 | AB41: =$AX25 -> 42095 | AC41: =$AX26 -> 42095 | AD41: =$AX27 -> 42093 | AE41: =$AX28 -> 42095 | AF41: =$AX29 -> 42095 | AG41: =$AX30 -> 42095 | AH41: =$AX31 -> NA | AI41: =$AX32 -> 2014 | AJ41: =$AX33 -> - | AL41: =$AX7 -> NUNEZ | AM41: =$AX8 -> JOSE JR | AN41: =$AX9 -> ADESAS | AO41: =$AX10 -> ERLINDA BACUETES NUNEZ | AP41: =$AX11 -> 352 RIZAL AVENUE BRGY 12 CATBALOGAN CITY SAMAR | AQ41: =$AX12 -> 184693732 | AR41: =$AX13 -> 112566 | AS41: =$AX15 -> PROVINCE OF SAMAR3 | AT41: DBP
G42: =ROUNDDOWN((NOW()-E42)/365,0) -> 126 | H42: =ROUNDDOWN((NOW()-F42)/365,0) -> 126 | L42: =J42+K42 -> 0 | O42: =IF(L42<10000,10%,IF(L42<13000,25%,30%)) -> 0.1 | P42: =L42*O42 -> 0 | Q42: =-PMT(W42/12,X42,V42) -> #NUM! | R42: =M42-N42+Q42 -> #NUM! | S42: =J42+K42-R42 -> #NUM! | T42: =IF(N42>0,"RENEWAL","NEW") -> NEW | U42: =-PV(W42/12,X42,P42) -> 0 | V42: ='COMPUTATION SHEET'!AA29 -> 0 | W42: =IF(X42>36,15.81%,12.651%) -> 0.12651 | X42: ='COMPUTATION SHEET'!AC29 -> 0 | Y42: =C42 -> 0 | AT42: DBP
C43: 4 | D43: =AZ37 -> LIMA, NESTOR PELENO | E43: =AZ13 -> 20219 | F43: =AZ14 -> 31048 | G43: =IF(E43>0,ROUNDDOWN((NOW()-E43)/365,0),0) -> 70 | H43: =IF(F43>0,ROUNDDOWN((NOW()-F43)/365,0),0) -> 41 | I43: =AZ17 -> PRISON GUARD I | J43: =AZ18 -> 12886 | K43: =AZ19 -> 2000 | L43: =J43+K43 -> 14886 | M43: =AZ20 -> 10386 | N43: =AZ21 -> 3453.19 | O43: =IF(L43<10000,10%,IF(L43<13000,25%,30%)) -> 0.3 | P43: =L43*O43 -> 4465.8 | Q43: =-PMT(W43/12,X43,V43) -> 3939.9077 | R43: =M43-N43+Q43 -> 10872.718 | S43: =J43+K43-R43 -> 4013.2823 | T43: =IF(N43>0,"RENEWAL","NEW") -> RENEWAL | U43: =-PV(W43/12,X43,P43) -> 158120.23 | V43: ='COMPUTATION SHEET'!AA30 -> 139500 | W43: =IF(X43>36,15.81%,12.651%) -> 0.1581 | X43: ='COMPUTATION SHEET'!AC30 -> 48 | Y43: =C43 -> 4 | Z43: =AZ23 -> 15-0080 | AA43: =$AZ24 -> 42094 | AB43: =$AZ25 -> 42087 | AC43: =$AZ26 -> 42093 | AD43: =$AZ27 -> 42087 | AE43: =$AZ28 -> 42087 | AF43: =$AZ29 -> 42087 | AG43: =$AZ30 -> 42087 | AH43: =$AZ31 -> NA | AI43: =$AZ32 -> 2014 | AJ43: =$AZ33 -> - | AL43: =$AZ7 -> LIMA | AM43: =$AZ8 -> NESTOR | AN43: =$AZ9 -> PELENO | AO43: =$AZ10 -> MARY GEN ISANAN LIMA | AP43: =$AZ11 -> PATONG STREET BRGY GUINSORONGAN CATBALOGAN CITY | AQ43: =$AZ12 -> 130157835 | AR43: =$AZ13 -> 20219 | AS43: =$AZ15 -> PROVINCE OF SAMAR4 | AT43: DBP
G44: =ROUNDDOWN((NOW()-E44)/365,0) -> 126 | H44: =ROUNDDOWN((NOW()-F44)/365,0) -> 126 | L44: =J44+K44 -> 0 | O44: =IF(L44<10000,10%,IF(L44<13000,25%,30%)) -> 0.1 | P44: =L44*O44 -> 0 | Q44: =-PMT(W44/12,X44,V44) -> #NUM! | R44: =M44-N44+Q44 -> #NUM! | S44: =J44+K44-R44 -> #NUM! | T44: =IF(N44>0,"RENEWAL","NEW") -> NEW | U44: =-PV(W44/12,X44,P44) -> 0 | V44: ='COMPUTATION SHEET'!AA31 -> 0 | W44: =IF(X44>36,15.81%,12.651%) -> 0.12651 | X44: ='COMPUTATION SHEET'!AC31 -> 0 | Y44: =C44 -> 0 | AT44: DBP
...

Sheet COMPUTATION SHEET
F1: DEVELOPMENT BANK OF THE PHILIPPINES | AH1: GUIDE
F2: =CONCATENATE(Signatories!C13," BRANCH, ",Signatories!C14) -> CATBALOGAN BRANCH, CATBALOGAN CITY, SAMAR | AH2: Years | AI2: Loanable | AJ2: Loan | AK2: Loan
AH3: in Service | AI3: Amount | AJ3: Term | AK3: Renewal
AH4: 1 | AI4: 3 | AJ4: 1 | AK4: 6 mos
F5: =LEFT('INPUT FIELDS'!D15,LEN('INPUT FIELDS'!D15)-1) -> PROVINCE OF SAMAR
F6: ='INPUT FIELDS'!D6 -> OT N0. 15-005 DATED APRIL 7, 2015 | AH6: 2 | AI6: 4 | AJ6: 2 | AK6: 1 year
AH7: 3 | AI7: 5 | AJ7: 3 | AK7: 1 year
B8: INPUT | C8: INPUT | H8: No. of Years in Service | J8: Monthly Basic Pay | K8: ACA/PERA/ RATA/ Others | L8: Gross | M8: Total Deductions Per Cert. of NTHP | N8: Less: Existing DBP Loan | P8: Maximum | R8: Maximum | S8: Add: New Amortization | T8: New Total Deductions | U8: Monthly Net Take Home pay | V8: Loan Type (New/Ren) | W8: NTHP | X8: NTHP | Y8: AMORT | AA8: Amount of Loan | AC8: Term of Loan (Months) | AD8: EVALUATION CHECK | AH8: 4 | AI8: 6 | AJ8: 3 | AK8: 1 year
B9: BIRTHDAY | C9: DATE | F9: Name of Applicant | G9: Age | I9: Position | L9: Monthly | O9: IGIR % | P9: Loan | Q9: IGIR % | R9: Loan | W9: add dbp | X9: less | Y9: TO | Z9: Maximum | AB9: Interest | AH9: 5 | AI9: 7 | AJ9: 3 | AK9: 1 year
C10: PERMANENT | L10: Income | P10: Installment | Q10: (if RENEWAL) | R10: Installment | W10: loan | X10: 4K GAA | Y10: USE | Z10: Loanable Amount | AB10: Rate | AH10: 6 | AI10: 8 | AJ10: 3 | AK10: 1 year
R11: (If RENEWAL) | Y11: (LI VS GAA) | AE11: IGIR | AF11: 4K NTHP
F12: PROVINCIAL ENGINEERING OFFICE
E14: 1 | G14: =ROUNDDOWN((NOW()-B14)/365,0) -> 126 | H14: =ROUNDDOWN((NOW()-C14)/365,0) -> 126 | N14: 0 | S14: =-PMT(15%/12,AC14,AA14) -> #REF! | T14: =M14-N14+S14 -> #REF! | U14: =J14+K14-T14 -> #REF! | V14: NEW | AA14: =ROUNDDOWN(J14*#REF!,-2) -> #REF! | AC14: 36 | AF14: =IF(U14<3000,"ALERT - NTHP IS BELOW 3K","GO") -> #REF! | AG14: =S14*2 -> #REF!
G15: =ROUNDDOWN((NOW()-B15)/365,0) -> 126 | H15: =ROUNDDOWN((NOW()-C15)/365,0) -> 126 | N15: 0 | T15: =M15-N15+S15 -> 0 | U15: =J15+K15-T15 -> 0 | AF15: =IF(J15<J14,"ALERT - ADD CO-MAKER", "GO") -> GO
G16: =ROUNDDOWN((NOW()-B16)/365,0) -> 126 | H16: =ROUNDDOWN((NOW()-C16)/365,0) -> 126 | N16: 0 | T16: =M16-N16+S16 -> 0 | U16: =J16+K16-T16 -> 0 | AF16: =IF(J16<J15,"ALERT - ADD CO-MAKER", "GO") -> GO
E18: 2 | G18: =ROUNDDOWN((NOW()-B18)/365,0) -> 126 | H18: =ROUNDDOWN((NOW()-C18)/365,0) -> 126 | N18: 0 | S18: =-PMT(15%/12,AC18,AA18) -> #REF! | T18: =M18-N18+S18 -> #REF! | U18: =J18+K18-T18 -> #REF! | V18: NEW | AA18: =ROUNDDOWN(J18*#REF!,-2) -> #REF! | AC18: 36 | AF18: =IF(U18<3000,"ALERT - NTHP IS BELOW 3K","GO") -> #REF! | AG18: =S18*2 -> #REF!
G19: =ROUNDDOWN((NOW()-B19)/365,0) -> 126 | H19: =ROUNDDOWN((NOW()-C19)/365,0) -> 126 | T19: =M19-N19+S19 -> 0 | U19: =J19+K19-T19 -> 0 | AF19: =IF(J19<J18,"ALERT - ADD CO-MAKER", "GO") -> GO
G20: =ROUNDDOWN((NOW()-B20)/365,0) -> 126 | H20: =ROUNDDOWN((NOW()-C20)/365,0) -> 126 | T20: =M20-N20+S20 -> 0 | U20: =J20+K20-T20 -> 0 | AF20: =IF(J20<J19,"ALERT - ADD CO-MAKER", "GO") -> GO
F23: =IF('INPUT FIELDS'!D16>0,'INPUT FIELDS'!D16,"") -> PROVINCIAL TREASURER OFFICE
B24: ='INPUT FIELDS'!E37 -> 29144 | C24: ='INPUT FIELDS'!F37 -> 39218 | E24: =IF(B24>0,1," ") -> 1 | F24: =IF(B24>0,'INPUT FIELDS'!D37," ") -> RABADAM, MARIA EMY TAN | G24: =IF(B24>0,'INPUT FIELDS'!G37," ") -> 46 | H24: =IF(B24>0,'INPUT FIELDS'!H37," ") -> 18 | I24: =IF(B24>0,'INPUT FIELDS'!I37," ") -> ADMIN AIDE I | J24: =IF(B24>0,'INPUT FIELDS'!J37," ") -> 38000 | K24: =IF(B24>0,'INPUT FIELDS'!K37," ") -> 2000 | L24: =IF(B24>0,'INPUT FIELDS'!L37," ") -> 40000 | M24: =IF(B24>0,'INPUT FIELDS'!M37," ") -> 26000 | N24: =IF(B24>0,'INPUT FIELDS'!N37," ") -> 5000 | O24: =IF(B24>0,IF(V24="NEW",'INPUT FIELDS'!O37,Q24)," ") -> 0.4 | P24: =IF(B24>0,IF(V24="NEW",'INPUT FIELDS'!P37,R24)," ") -> 16000 | Q24: =IF(L24<10000,20%,IF(L24<13000,30%,IF(L24<38000,35%,40%))) -> 0.4 | R24: =Q24*L24 -> 16000 | S24: =IF(B24>0,'INPUT FIELDS'!Q37," ") -> 6392.3145 | T24: =IF(B24>0,'INPUT FIELDS'!R37," ") -> 27392.315 | U24: =IF(B24>0,'INPUT FIELDS'!S37," ") -> 12607.685 | V24: =IF(B24>0,'INPUT FIELDS'!T37," ") -> RENEWAL | W24: =L24-M24+N24 -> 19000 | X24: =W24-4000 -> 15000 | Y24: =IF(P24<X24,P24,X24) -> 15000 | Z24: =IF(B24>0,-PV(AB24/12,AC24,Y24),"") -> 168248.92 | AA24: 71700 | AB24: =IF(B24>0,'INPUT FIELDS'!W37," ") -> 0.12651 | AC24: 12 | AE24: =IF(AA24>0,IF(P24<S24,"CHK IGIR","GO")," ") -> GO | AF24: =IF(AA24>0,IF(U24<4000," NTHP BELOW 4K","GO")," ") -> GO
F25: =IF('INPUT FIELDS'!AV16>0,'INPUT FIELDS'!AV16,"") -> PROVINCIAL ENGINEERING OFFICE | G25: =IF(E25>0,'INPUT FIELDS'!G38," ") | H25: =IF(E25>0,'INPUT FIELDS'!H38," ") | I25: =IF(E25>0,'INPUT FIELDS'!I38," ") | J25: =IF(E25>0,'INPUT FIELDS'!J38," ") | K25: =IF(E25>0,'INPUT FIELDS'!K38," ") | L25: =IF(E25>0,'INPUT FIELDS'!L38," ") | M25: =IF(E25>0,'INPUT FIELDS'!M38," ") | N25: =IF(E25>0,'INPUT FIELDS'!N38," ") | O25: =IF(E25>0,'INPUT FIELDS'!O38," ") | P25: =IF(E25>0,'INPUT FIELDS'!P38," ") | S25: =IF(E25>0,'INPUT FIELDS'!Q38," ") | T25: =IF(E25>0,'INPUT FIELDS'!R38," ") | U25: =IF(E25>0,'INPUT FIELDS'!S38," ") | V25: =IF(E25>0,'INPUT FIELDS'!T38," ") | Z25: =IF(E25>0,'INPUT FIELDS'!U38," ")
B26: ='INPUT FIELDS'!E39 -> 30469 | C26: ='INPUT FIELDS'!F39 -> 40525 | E26: =IF(B26>0,2," ") -> 2 | F26: =IF(B26>0,'INPUT FIELDS'!D39," ") -> LEJAS, ALLAN GULFERIC | G26: =IF(B26>0,'INPUT FIELDS'!G39," ") -> 42 | H26: =IF(B26>0,'INPUT FIELDS'!H39," ") -> 15 | I26: =IF(B26>0,'INPUT FIELDS'!I39," ") -> CM CAPATAZ | J26: =IF(B26>0,'INPUT FIELDS'!J39," ") -> 12139 | K26: =IF(B26>0,'INPUT FIELDS'!K39," ") -> 2000 | L26: =IF(B26>0,'INPUT FIELDS'!L39," ") -> 14139 | M26: =IF(B26>0,'INPUT FIELDS'!M39," ") -> 6939.36 | N26: =IF(B26>0,'INPUT FIELDS'!N39," ") -> 0 | O26: =IF(B26>0,IF(V26="NEW",'INPUT FIELDS'!O39,Q26)," ") -> 0.3 | P26: =IF(B26>0,IF(V26="NEW",'INPUT FIELDS'!P39,R26)," ") -> 4241.7 | Q26: =IF(L26<10000,20%,IF(L26<13000,30%,IF(L26<38000,35%,40%))) -> 0.35 | R26: =Q26*L26 -> 4948.65 | S26: =IF(B26>0,'INPUT FIELDS'!Q39," ") -> 3191.4665 | T26: =IF(B26>0,'INPUT FIELDS'!R39," ") -> 10130.826 | U26: =IF(B26>0,'INPUT FIELDS'!S39," ") -> 4008.1735 | V26: =IF(B26>0,'INPUT FIELDS'!T39," ") -> NEW | W26: =L26-M26+N26 -> 7199.64 | X26: =W26-4000 -> 3199.64 | Y26: =IF(P26<X26,P26,X26) -> 3199.64 | Z26: =IF(B26>0,-PV(AB26/12,AC26,Y26),"") -> 113289.4 | AA26: 113000 | AB26: =IF(B26>0,'INPUT FIELDS'!W39," ") -> 0.1581 | AC26: 48 | AE26: =IF(AA26>0,IF(P26<S26,"CHK IGIR","GO")," ") -> GO | AF26: =IF(AA26>0,IF(U26<4000," NTHP BELOW 4K","GO")," ") -> GO
F27: =IF('INPUT FIELDS'!AX16>0,'INPUT FIELDS'!AX16,"") -> PROVINCIAL AGRICULTURE OFFICE | G27: =IF(E27>0,'INPUT FIELDS'!G40," ") | H27: =IF(E27>0,'INPUT FIELDS'!H40," ") | I27: =IF(E27>0,'INPUT FIELDS'!I40," ") | J27: =IF(E27>0,'INPUT FIELDS'!J40," ") | K27: =IF(E27>0,'INPUT FIELDS'!K40," ") | L27: =IF(E27>0,'INPUT FIELDS'!L40," ") | M27: =IF(E27>0,'INPUT FIELDS'!M40," ") | N27: =IF(E27>0,'INPUT FIELDS'!N40," ") | O27: =IF(E27>0,'INPUT FIELDS'!O40," ") | P27: =IF(E27>0,'INPUT FIELDS'!P40," ") | S27: =IF(E27>0,'INPUT FIELDS'!Q40," ") | T27: =IF(E27>0,'INPUT FIELDS'!R40," ") | U27: =IF(E27>0,'INPUT FIELDS'!S40," ") | V27: =IF(E27>0,'INPUT FIELDS'!T40," ") | Z27: =IF(E27>0,'INPUT FIELDS'!U40," ")
B28: ='INPUT FIELDS'!E41 -> 112566 | C28: ='INPUT FIELDS'!F41 -> 34541 | E28: =IF(B28>0,3," ") -> 3 | F28: =IF(B28>0,'INPUT FIELDS'!D41," ") -> NUNEZ, JOSE JR ADESAS | G28: =IF(B28>0,'INPUT FIELDS'!G41," ") -> -182 | H28: =IF(B28>0,'INPUT FIELDS'!H41," ") -> 31 | I28: =IF(B28>0,'INPUT FIELDS'!I41," ") -> DRAFTSMAN I | J28: =IF(B28>0,'INPUT FIELDS'!J41," ") -> 13853 | K28: =IF(B28>0,'INPUT FIELDS'!K41," ") -> 2000 | L28: =IF(B28>0,'INPUT FIELDS'!L41," ") -> 15853 | M28: =IF(B28>0,'INPUT FIELDS'!M41," ") -> 9753.9 | N28: =IF(B28>0,'INPUT FIELDS'!N41," ") -> 3714.69 | O28: =IF(B28>0,IF(V28="NEW",'INPUT FIELDS'!O41,Q28)," ") -> 0.35 | P28: =IF(B28>0,IF(V28="NEW",'INPUT FIELDS'!P41,R28)," ") -> 5548.55 | Q28: =IF(L28<10000,20%,IF(L28<13000,30%,IF(L28<38000,35%,40%))) -> 0.35 | R28: =Q28*L28 -> 5548.55 | S28: =IF(B28>0,'INPUT FIELDS'!Q41," ") -> 5546.9382 | T28: =IF(B28>0,'INPUT FIELDS'!R41," ") -> 11586.148 | U28: =IF(B28>0,'INPUT FIELDS'!S41," ") -> 4266.8518 | V28: =IF(B28>0,'INPUT FIELDS'!T41," ") -> RENEWAL | W28: =L28-M28+N28 -> 9813.79 | X28: =W28-4000 -> 5813.79 | Y28: =IF(P28<X28,P28,X28) -> 5548.55 | Z28: =IF(B28>0,-PV(AB28/12,AC28,Y28),"") -> 196457.07 | AA28: 196400 | AB28: =IF(B28>0,'INPUT FIELDS'!W41," ") -> 0.1581 | AC28: 48 | AE28: =IF(AA28>0,IF(P28<S28,"CHK IGIR","GO")," ") -> GO | AF28: =IF(AA28>0,IF(U28<4000," NTHP BELOW 4K","GO")," ") -> GO
F29: =IF('INPUT FIELDS'!AZ16>0,'INPUT FIELDS'!AZ16,"") -> PROVINCIAL WARDENS OFFICE | G29: =IF(E29>0,'INPUT FIELDS'!G42," ") | H29: =IF(E29>0,'INPUT FIELDS'!H42," ") | I29: =IF(E29>0,'INPUT FIELDS'!I42," ") | J29: =IF(E29>0,'INPUT FIELDS'!J42," ") | K29: =IF(E29>0,'INPUT FIELDS'!K42," ") | L29: =IF(E29>0,'INPUT FIELDS'!L42," ") | M29: =IF(E29>0,'INPUT FIELDS'!M42," ") | N29: =IF(E29>0,'INPUT FIELDS'!N42," ") | O29: =IF(E29>0,'INPUT FIELDS'!O42," ") | P29: =IF(E29>0,'INPUT FIELDS'!P42," ") | S29: =IF(E29>0,'INPUT FIELDS'!Q42," ") | T29: =IF(E29>0,'INPUT FIELDS'!R42," ") | U29: =IF(E29>0,'INPUT FIELDS'!S42," ") | V29: =IF(E29>0,'INPUT FIELDS'!T42," ") | Z29: =IF(E29>0,'INPUT FIELDS'!U42," ")
B30: ='INPUT FIELDS'!E43 -> 20219 | C30: ='INPUT FIELDS'!F43 -> 31048 | E30: =IF(B30>0,4," ") -> 4 | F30: =IF(B30>0,'INPUT FIELDS'!D43," ") -> LIMA, NESTOR PELENO | G30: =IF(B30>0,'INPUT FIELDS'!G43," ") -> 70 | H30: =IF(B30>0,'INPUT FIELDS'!H43," ") -> 41 | I30: =IF(B30>0,'INPUT FIELDS'!I43," ") -> PRISON GUARD I | J30: =IF(B30>0,'INPUT FIELDS'!J43," ") -> 12886 | K30: =IF(B30>0,'INPUT FIELDS'!K43," ") -> 2000 | L30: =IF(B30>0,'INPUT FIELDS'!L43," ") -> 14886 | M30: =IF(B30>0,'INPUT FIELDS'!M43," ") -> 10386 | N30: =IF(B30>0,'INPUT FIELDS'!N43," ") -> 3453.19 | O30: =IF(B30>0,IF(V30="NEW",'INPUT FIELDS'!O43,Q30)," ") -> 0.35 | P30: =IF(B30>0,IF(V30="NEW",'INPUT FIELDS'!P43,R30)," ") -> 5210.1 | Q30: =IF(L30<10000,20%,IF(L30<13000,30%,IF(L30<38000,35%,40%))) -> 0.35 | R30: =Q30*L30 -> 5210.1 | S30: =IF(B30>0,'INPUT FIELDS'!Q43," ") -> 3939.9077 | T30: =IF(B30>0,'INPUT FIELDS'!R43," ") -> 10872.718 | U30: =IF(B30>0,'INPUT FIELDS'!S43," ") -> 4013.2823 | V30: =IF(B30>0,'INPUT FIELDS'!T43," ") -> RENEWAL | W30: =L30-M30+N30 -> 7953.19 | X30: =W30-4000 -> 3953.19 | Y30: =IF(P30<X30,P30,X30) -> 3953.19 | Z30: =IF(B30>0,-PV(AB30/12,AC30,Y30),"") -> 139970.28 | AA30: 139500 | AB30: =IF(B30>0,'INPUT FIELDS'!W43," ") -> 0.1581 | AC30: 48 | AE30: =IF(AA30>0,IF(P30<S30,"CHK IGIR","GO")," ") -> GO | AF30: =IF(AA30>0,IF(U30<4000," NTHP BELOW 4K","GO")," ") -> GO
F31: =IF('INPUT FIELDS'!BB16>0,'INPUT FIELDS'!BB16,"") -> PROVINCIAL WARDENS OFFICE | G31: =IF(E31>0,'INPUT FIELDS'!G44," ") | H31: =IF(E31>0,'INPUT FIELDS'!H44," ") | I31: =IF(E31>0,'INPUT FIELDS'!I44," ") | J31: =IF(E31>0,'INPUT FIELDS'!J44," ") | K31: =IF(E31>0,'INPUT FIELDS'!K44," ") | L31: =IF(E31>0,'INPUT FIELDS'!L44," ") | M31: =IF(E31>0,'INPUT FIELDS'!M44," ") | N31: =IF(E31>0,'INPUT FIELDS'!N44," ") | O31: =IF(E31>0,'INPUT FIELDS'!O44," ") | P31: =IF(E31>0,'INPUT FIELDS'!P44," ") | S31: =IF(E31>0,'INPUT FIELDS'!Q44," ") | T31: =IF(E31>0,'INPUT FIELDS'!R44," ") | U31: =IF(E31>0,'INPUT FIELDS'!S44," ") | V31: =IF(E31>0,'INPUT FIELDS'!T44," ") | Z31: =IF(E31>0,'INPUT FIELDS'!U44," ")
B32: ='INPUT FIELDS'!E45 -> 26900 | C32: ='INPUT FIELDS'!F45 -> 36297 | E32: =IF(B32>0,5," ") -> 5 | F32: =IF(B32>0,'INPUT FIELDS'!D45," ") -> ALEGRIA, MARCIANO JR HERNANDEZ | G32: =IF(B32>0,'INPUT FIELDS'!G45," ") -> 52 | H32: =IF(B32>0,'INPUT FIELDS'!H45," ") -> 26 | I32: =IF(B32>0,'INPUT FIELDS'!I45," ") -> ADMIN AIDE III | J32: =IF(B32>0,'INPUT FIELDS'!J45," ") -> 10931 | K32: =IF(B32>0,'INPUT FIELDS'!K45," ") -> 2000 | L32: =IF(B32>0,'INPUT FIELDS'!L45," ") -> 12931 | M32: =IF(B32>0,'INPUT FIELDS'!M45," ") -> 7761 | N32: =IF(B32>0,'INPUT FIELDS'!N45," ") -> 2999.23 | O32: =IF(B32>0,IF(V32="NEW",'INPUT FIELDS'!O45,Q32)," ") -> 0.3 | P32: =IF(B32>0,IF(V32="NEW",'INPUT FIELDS'!P45,R32)," ") -> 3879.3 | Q32: =IF(L32<10000,20%,IF(L32<13000,30%,IF(L32<38000,35%,40%))) -> 0.3 | R32: =Q32*L32 -> 3879.3 | S32: =IF(B32>0,'INPUT FIELDS'!Q45," ") -> 3879.1852 | T32: =IF(B32>0,'INPUT FIELDS'!R45," ") -> 8640.9552 | U32: =IF(B32>0,'INPUT FIELDS'!S45," ") -> 4290.0448 | V32: =IF(B32>0,'INPUT FIELDS'!T45," ") -> RENEWAL | W32: =L32-M32+N32 -> 8169.23 | X32: =W32-4000 -> 4169.23 | Y32: =IF(P32<X32,P32,X32) -> 3879.3 | Z32: =IF(B32>0,-PV(AB32/12,AC32,Y32),"") -> 137354.07 | AA32: 137350 | AB32: =IF(B32>0,'INPUT FIELDS'!W45," ") -> 0.1581 | AC32: 48 | AE32: =IF(AA32>0,IF(P32<S32,"CHK IGIR","GO")," ") -> GO | AF32: =IF(AA32>0,IF(U32<4000," NTHP BELOW 4K","GO")," ") -> GO
F33: =IF('INPUT FIELDS'!BD16>0,'INPUT FIELDS'!BD16,"") -> PROVINCIAL HEALTH OFFICE | G33: =IF(E33>0,'INPUT FIELDS'!G46," ") | H33: =IF(E33>0,'INPUT FIELDS'!H46," ") | I33: =IF(E33>0,'INPUT FIELDS'!I46," ") | J33: =IF(E33>0,'INPUT FIELDS'!J46," ") | K33: =IF(E33>0,'INPUT FIELDS'!K46," ") | L33: =IF(E33>0,'INPUT FIELDS'!L46," ") | M33: =IF(E33>0,'INPUT FIELDS'!M46," ") | N33: =IF(E33>0,'INPUT FIELDS'!N46," ") | O33: =IF(E33>0,'INPUT FIELDS'!O46," ") | P33: =IF(E33>0,'INPUT FIELDS'!P46," ") | S33: =IF(E33>0,'INPUT FIELDS'!Q46," ") | T33: =IF(E33>0,'INPUT FIELDS'!R46," ") | U33: =IF(E33>0,'INPUT FIELDS'!S46," ") | V33: =IF(E33>0,'INPUT FIELDS'!T46," ") | Z33: =IF(E33>0,'INPUT FIELDS'!U46," ")
